<?xml version="1.0"?>
<robot name="pinocchio">
  
  <link name="base_link">
    <visual>
      <geometry>
       <!--<box size="0.6 0.5 .4"/>-->
	<mesh filename="package://robot_model/urdf/Pinocchio_Frame.STL"/>
	
      </geometry>
	<material name="blue">
        <color rgba="0.5 0.5 .5 1"/>
	</material>
	<origin rpy="1.57 0 1.57" xyz="-0.1 0 0.05"/>
    </visual>
  </link>
	
<link name="left_wheel">
    <visual>
      <geometry>
       <!-- <cylinder length="0.1" radius="0.15"/>-->
<mesh filename="package://robot_model/urdf/wheel_talos.STL"/>
      </geometry>
	<material name="black">
        <color rgba="0.1 0.1 .1 1"/>
	</material>
	<origin rpy="0  -1.57 0" xyz="0.045 -0.06 -0.2"/>
    </visual>
  </link>
<link name="right_wheel">
    <visual>
      <geometry>
              <!-- <cylinder length="0.1" radius="0.15"/>-->
		<mesh filename="package://robot_model/urdf/wheel_talos.STL"/>
      </geometry>
	<material name="black">
        <color rgba="0 0 .1 1"/>
	</material>
	<origin rpy="0  -1.57 0" xyz="0.045 -0.06 -0.2"/>
    </visual>
  </link>
	
 <link name="left_wheel_back">
    <visual>
      <geometry>
              <!-- <cylinder length="0.1" radius="0.15"/>-->
		<mesh filename="package://robot_model/urdf/wheel_talos.STL"/>
      </geometry>
	<material name="black">
        <color rgba="0 0 .1 1"/>
	</material>
	<origin rpy="0  -1.57 0" xyz="0.045 -0.06 -0.2"/>
    </visual>
  </link>
<link name="right_wheel_back">
    <visual>
      <geometry>
        	<!-- <cylinder length="0.1" radius="0.15"/>-->
		<mesh filename="package://robot_model/urdf/wheel_talos.STL"/>
      </geometry>
	<material name="black">
        <color rgba="0 0 .1 1"/>
	</material>
	<origin rpy="0  -1.57 0" xyz="0.045 -0.06 -0.2"/>
    </visual>
  </link>

<link name="laser_front">
    <visual>
      <geometry>
       <!--cylinder length="0.1" radius="0.1"/>-->
	<mesh filename="package://robot_model/urdf/sick_tim551.stl"/>
      </geometry>
	<material name="white">
        <color rgba="0.9 0.9 .9 1"/>
	</material>
	<origin rpy="0 0 0" xyz="0.0 -0.0 0.0"/>
    </visual>
  </link>
 
 <joint name="base_to_left_wheel" type="floating">
    <parent link="base_link"/>
    <child link="left_wheel"/>
  </joint>
<joint name="base_to_right_wheel" type="floating">
    <parent link="base_link"/>
    <child link="right_wheel"/>
  </joint>	
  <joint name="base_to_left_wheel2" type="floating">
    <parent link="base_link"/>
    <child link="left_wheel_back"/>
  </joint>
<joint name="base_to_right_wheel2" type="floating">
    <parent link="base_link"/>
    <child link="right_wheel_back"/>
  </joint>

 <joint name="base_laser_front" type="floating">
    <parent link="base_link"/>
    <child link="laser_front"/>
  </joint>


</robot>

